[2024-12-05T10:17:59.473+0000] {taskinstance.py:1103} INFO - Dependencies all met for dep_context=non-requeueable deps ti=<TaskInstance: etl_file_processing.etl_process_ih manual__2024-12-05T10:17:57.233337+00:00 [queued]>
[2024-12-05T10:17:59.481+0000] {taskinstance.py:1103} INFO - Dependencies all met for dep_context=requeueable deps ti=<TaskInstance: etl_file_processing.etl_process_ih manual__2024-12-05T10:17:57.233337+00:00 [queued]>
[2024-12-05T10:17:59.481+0000] {taskinstance.py:1308} INFO - Starting attempt 1 of 2
[2024-12-05T10:17:59.498+0000] {taskinstance.py:1327} INFO - Executing <Task(PythonOperator): etl_process_ih> on 2024-12-05 10:17:57.233337+00:00
[2024-12-05T10:17:59.526+0000] {standard_task_runner.py:57} INFO - Started process 404 to run task
[2024-12-05T10:17:59.542+0000] {standard_task_runner.py:84} INFO - Running: ['***', 'tasks', 'run', 'etl_file_processing', 'etl_process_ih', 'manual__2024-12-05T10:17:57.233337+00:00', '--job-id', '179', '--raw', '--subdir', 'DAGS_FOLDER/ETL_file_processing.py', '--cfg-path', '/tmp/tmp1casiebn']
[2024-12-05T10:17:59.545+0000] {standard_task_runner.py:85} INFO - Job 179: Subtask etl_process_ih
[2024-12-05T10:17:59.630+0000] {task_command.py:410} INFO - Running <TaskInstance: etl_file_processing.etl_process_ih manual__2024-12-05T10:17:57.233337+00:00 [running]> on host effe9442f8f2
[2024-12-05T10:17:59.731+0000] {taskinstance.py:1547} INFO - Exporting env vars: AIRFLOW_CTX_DAG_OWNER='***' AIRFLOW_CTX_DAG_ID='etl_file_processing' AIRFLOW_CTX_TASK_ID='etl_process_ih' AIRFLOW_CTX_EXECUTION_DATE='2024-12-05T10:17:57.233337+00:00' AIRFLOW_CTX_TRY_NUMBER='1' AIRFLOW_CTX_DAG_RUN_ID='manual__2024-12-05T10:17:57.233337+00:00'
[2024-12-05T10:17:59.752+0000] {taskinstance.py:1824} ERROR - Task failed with exception
Traceback (most recent call last):
  File "/home/airflow/.local/lib/python3.7/site-packages/airflow/operators/python.py", line 181, in execute
    return_value = self.execute_callable()
  File "/home/airflow/.local/lib/python3.7/site-packages/airflow/operators/python.py", line 198, in execute_callable
    return self.python_callable(*self.op_args, **self.op_kwargs)
  File "/opt/airflow/dags/ETL_file_processing.py", line 62, in etl_process_ih
    db = client[DB_NAME]
  File "/home/airflow/.local/lib/python3.7/site-packages/pymongo/mongo_client.py", line 1641, in __getitem__
    return database.Database(self, name)
  File "/home/airflow/.local/lib/python3.7/site-packages/pymongo/database.py", line 136, in __init__
    raise TypeError("name must be an instance of str")
TypeError: name must be an instance of str
[2024-12-05T10:17:59.760+0000] {taskinstance.py:1350} INFO - Marking task as UP_FOR_RETRY. dag_id=etl_file_processing, task_id=etl_process_ih, execution_date=20241205T101757, start_date=20241205T101759, end_date=20241205T101759
[2024-12-05T10:17:59.770+0000] {standard_task_runner.py:109} ERROR - Failed to execute job 179 for task etl_process_ih (name must be an instance of str; 404)
[2024-12-05T10:17:59.796+0000] {local_task_job_runner.py:225} INFO - Task exited with return code 1
[2024-12-05T10:17:59.827+0000] {taskinstance.py:2653} INFO - 0 downstream tasks scheduled from follow-on schedule check
