[2024-12-05T10:23:15.854+0000] {taskinstance.py:1103} INFO - Dependencies all met for dep_context=non-requeueable deps ti=<TaskInstance: etl_file_processing.etl_process_ih manual__2024-12-05T10:18:11.041689+00:00 [queued]>
[2024-12-05T10:23:15.867+0000] {taskinstance.py:1103} INFO - Dependencies all met for dep_context=requeueable deps ti=<TaskInstance: etl_file_processing.etl_process_ih manual__2024-12-05T10:18:11.041689+00:00 [queued]>
[2024-12-05T10:23:15.867+0000] {taskinstance.py:1308} INFO - Starting attempt 2 of 2
[2024-12-05T10:23:15.882+0000] {taskinstance.py:1327} INFO - Executing <Task(PythonOperator): etl_process_ih> on 2024-12-05 10:18:11.041689+00:00
[2024-12-05T10:23:15.894+0000] {standard_task_runner.py:57} INFO - Started process 84 to run task
[2024-12-05T10:23:15.901+0000] {standard_task_runner.py:84} INFO - Running: ['***', 'tasks', 'run', 'etl_file_processing', 'etl_process_ih', 'manual__2024-12-05T10:18:11.041689+00:00', '--job-id', '191', '--raw', '--subdir', 'DAGS_FOLDER/ETL_file_processing.py', '--cfg-path', '/tmp/tmprx0xe6oq']
[2024-12-05T10:23:15.903+0000] {standard_task_runner.py:85} INFO - Job 191: Subtask etl_process_ih
[2024-12-05T10:23:15.984+0000] {task_command.py:410} INFO - Running <TaskInstance: etl_file_processing.etl_process_ih manual__2024-12-05T10:18:11.041689+00:00 [running]> on host 56e009f5c9b1
[2024-12-05T10:23:16.061+0000] {taskinstance.py:1547} INFO - Exporting env vars: AIRFLOW_CTX_DAG_OWNER='***' AIRFLOW_CTX_DAG_ID='etl_file_processing' AIRFLOW_CTX_TASK_ID='etl_process_ih' AIRFLOW_CTX_EXECUTION_DATE='2024-12-05T10:18:11.041689+00:00' AIRFLOW_CTX_TRY_NUMBER='2' AIRFLOW_CTX_DAG_RUN_ID='manual__2024-12-05T10:18:11.041689+00:00'
[2024-12-05T10:23:16.095+0000] {taskinstance.py:1824} ERROR - Task failed with exception
Traceback (most recent call last):
  File "/home/airflow/.local/lib/python3.7/site-packages/airflow/operators/python.py", line 181, in execute
    return_value = self.execute_callable()
  File "/home/airflow/.local/lib/python3.7/site-packages/airflow/operators/python.py", line 198, in execute_callable
    return self.python_callable(*self.op_args, **self.op_kwargs)
  File "/opt/airflow/dags/ETL_file_processing.py", line 62, in etl_process_ih
    db = client[DB_NAME]
  File "/home/airflow/.local/lib/python3.7/site-packages/pymongo/mongo_client.py", line 1641, in __getitem__
    return database.Database(self, name)
  File "/home/airflow/.local/lib/python3.7/site-packages/pymongo/database.py", line 136, in __init__
    raise TypeError("name must be an instance of str")
TypeError: name must be an instance of str
[2024-12-05T10:23:16.111+0000] {taskinstance.py:1350} INFO - Marking task as FAILED. dag_id=etl_file_processing, task_id=etl_process_ih, execution_date=20241205T101811, start_date=20241205T102315, end_date=20241205T102316
[2024-12-05T10:23:16.123+0000] {standard_task_runner.py:109} ERROR - Failed to execute job 191 for task etl_process_ih (name must be an instance of str; 84)
[2024-12-05T10:23:16.164+0000] {local_task_job_runner.py:225} INFO - Task exited with return code 1
[2024-12-05T10:23:16.189+0000] {taskinstance.py:2653} INFO - 0 downstream tasks scheduled from follow-on schedule check
