[2024-12-04T14:06:44.012+0000] {taskinstance.py:1103} INFO - Dependencies all met for dep_context=non-requeueable deps ti=<TaskInstance: FoReport_file_processing.etl_process_request manual__2024-12-04T14:01:15.945826+00:00 [queued]>
[2024-12-04T14:06:44.021+0000] {taskinstance.py:1103} INFO - Dependencies all met for dep_context=requeueable deps ti=<TaskInstance: FoReport_file_processing.etl_process_request manual__2024-12-04T14:01:15.945826+00:00 [queued]>
[2024-12-04T14:06:44.022+0000] {taskinstance.py:1308} INFO - Starting attempt 2 of 2
[2024-12-04T14:06:44.036+0000] {taskinstance.py:1327} INFO - Executing <Task(PythonOperator): etl_process_request> on 2024-12-04 14:01:15.945826+00:00
[2024-12-04T14:06:44.055+0000] {standard_task_runner.py:57} INFO - Started process 222 to run task
[2024-12-04T14:06:44.070+0000] {standard_task_runner.py:84} INFO - Running: ['***', 'tasks', 'run', 'FoReport_file_processing', 'etl_process_request', 'manual__2024-12-04T14:01:15.945826+00:00', '--job-id', '48', '--raw', '--subdir', 'DAGS_FOLDER/FoReport_file_processing.py', '--cfg-path', '/tmp/tmp6ui8s1su']
[2024-12-04T14:06:44.071+0000] {standard_task_runner.py:85} INFO - Job 48: Subtask etl_process_request
[2024-12-04T14:06:44.140+0000] {task_command.py:410} INFO - Running <TaskInstance: FoReport_file_processing.etl_process_request manual__2024-12-04T14:01:15.945826+00:00 [running]> on host effe9442f8f2
[2024-12-04T14:06:44.204+0000] {taskinstance.py:1547} INFO - Exporting env vars: AIRFLOW_CTX_DAG_OWNER='***' AIRFLOW_CTX_DAG_ID='FoReport_file_processing' AIRFLOW_CTX_TASK_ID='etl_process_request' AIRFLOW_CTX_EXECUTION_DATE='2024-12-04T14:01:15.945826+00:00' AIRFLOW_CTX_TRY_NUMBER='2' AIRFLOW_CTX_DAG_RUN_ID='manual__2024-12-04T14:01:15.945826+00:00'
[2024-12-04T14:06:45.265+0000] {taskinstance.py:1824} ERROR - Task failed with exception
Traceback (most recent call last):
  File "/home/airflow/.local/lib/python3.7/site-packages/airflow/operators/python.py", line 181, in execute
    return_value = self.execute_callable()
  File "/home/airflow/.local/lib/python3.7/site-packages/airflow/operators/python.py", line 198, in execute_callable
    return self.python_callable(*self.op_args, **self.op_kwargs)
  File "/opt/airflow/dags/FoReport_file_processing.py", line 112, in etl_process_request
    cleaned_df = merged_df.drop_duplicates(subset=["Room_Number", "Arrival", "Depart"], keep="last")
  File "/home/airflow/.local/lib/python3.7/site-packages/pandas/util/_decorators.py", line 311, in wrapper
    return func(*args, **kwargs)
  File "/home/airflow/.local/lib/python3.7/site-packages/pandas/core/frame.py", line 6063, in drop_duplicates
    duplicated = self.duplicated(subset, keep=keep)
  File "/home/airflow/.local/lib/python3.7/site-packages/pandas/core/frame.py", line 6197, in duplicated
    raise KeyError(diff)
KeyError: Index(['Arrival', 'Depart', 'Room_Number'], dtype='object')
[2024-12-04T14:06:45.299+0000] {taskinstance.py:1350} INFO - Marking task as FAILED. dag_id=FoReport_file_processing, task_id=etl_process_request, execution_date=20241204T140115, start_date=20241204T140644, end_date=20241204T140645
[2024-12-04T14:06:45.321+0000] {standard_task_runner.py:109} ERROR - Failed to execute job 48 for task etl_process_request (Index(['Arrival', 'Depart', 'Room_Number'], dtype='object'); 222)
[2024-12-04T14:06:45.359+0000] {local_task_job_runner.py:225} INFO - Task exited with return code 1
[2024-12-04T14:06:45.421+0000] {taskinstance.py:2653} INFO - 0 downstream tasks scheduled from follow-on schedule check
