[2024-12-05T10:29:25.308+0000] {taskinstance.py:1103} INFO - Dependencies all met for dep_context=non-requeueable deps ti=<TaskInstance: etl_file_processing.etl_process_ih manual__2024-12-05T10:24:20.537151+00:00 [queued]>
[2024-12-05T10:29:25.320+0000] {taskinstance.py:1103} INFO - Dependencies all met for dep_context=requeueable deps ti=<TaskInstance: etl_file_processing.etl_process_ih manual__2024-12-05T10:24:20.537151+00:00 [queued]>
[2024-12-05T10:29:25.320+0000] {taskinstance.py:1308} INFO - Starting attempt 2 of 2
[2024-12-05T10:29:25.339+0000] {taskinstance.py:1327} INFO - Executing <Task(PythonOperator): etl_process_ih> on 2024-12-05 10:24:20.537151+00:00
[2024-12-05T10:29:25.352+0000] {standard_task_runner.py:57} INFO - Started process 125 to run task
[2024-12-05T10:29:25.359+0000] {standard_task_runner.py:84} INFO - Running: ['***', 'tasks', 'run', 'etl_file_processing', 'etl_process_ih', 'manual__2024-12-05T10:24:20.537151+00:00', '--job-id', '199', '--raw', '--subdir', 'DAGS_FOLDER/ETL_file_processing.py', '--cfg-path', '/tmp/tmpy_i3lw37']
[2024-12-05T10:29:25.364+0000] {standard_task_runner.py:85} INFO - Job 199: Subtask etl_process_ih
[2024-12-05T10:29:25.450+0000] {task_command.py:410} INFO - Running <TaskInstance: etl_file_processing.etl_process_ih manual__2024-12-05T10:24:20.537151+00:00 [running]> on host 56e009f5c9b1
[2024-12-05T10:29:25.608+0000] {taskinstance.py:1547} INFO - Exporting env vars: AIRFLOW_CTX_DAG_OWNER='***' AIRFLOW_CTX_DAG_ID='etl_file_processing' AIRFLOW_CTX_TASK_ID='etl_process_ih' AIRFLOW_CTX_EXECUTION_DATE='2024-12-05T10:24:20.537151+00:00' AIRFLOW_CTX_TRY_NUMBER='2' AIRFLOW_CTX_DAG_RUN_ID='manual__2024-12-05T10:24:20.537151+00:00'
[2024-12-05T10:29:55.928+0000] {taskinstance.py:1824} ERROR - Task failed with exception
Traceback (most recent call last):
  File "/home/airflow/.local/lib/python3.7/site-packages/airflow/operators/python.py", line 181, in execute
    return_value = self.execute_callable()
  File "/home/airflow/.local/lib/python3.7/site-packages/airflow/operators/python.py", line 198, in execute_callable
    return self.python_callable(*self.op_args, **self.op_kwargs)
  File "/opt/airflow/dags/ETL_file_processing.py", line 66, in etl_process_ih
    etl_collection.delete_many({})
  File "/home/airflow/.local/lib/python3.7/site-packages/pymongo/collection.py", line 1459, in delete_many
    comment=comment,
  File "/home/airflow/.local/lib/python3.7/site-packages/pymongo/collection.py", line 1331, in _delete_retryable
    operation=_Op.DELETE,
  File "/home/airflow/.local/lib/python3.7/site-packages/pymongo/mongo_client.py", line 1569, in _retryable_write
    return self._retry_with_session(retryable, func, s, bulk, operation, operation_id)
  File "/home/airflow/.local/lib/python3.7/site-packages/pymongo/mongo_client.py", line 1461, in _retry_with_session
    operation_id=operation_id,
  File "/home/airflow/.local/lib/python3.7/site-packages/pymongo/_csot.py", line 108, in csot_wrapper
    return func(self, *args, **kwargs)
  File "/home/airflow/.local/lib/python3.7/site-packages/pymongo/mongo_client.py", line 1500, in _retry_internal
    operation_id=operation_id,
  File "/home/airflow/.local/lib/python3.7/site-packages/pymongo/mongo_client.py", line 2347, in run
    return self._read() if self._is_read else self._write()
  File "/home/airflow/.local/lib/python3.7/site-packages/pymongo/mongo_client.py", line 2450, in _write
    self._server = self._get_server()
  File "/home/airflow/.local/lib/python3.7/site-packages/pymongo/mongo_client.py", line 2439, in _get_server
    operation_id=self._operation_id,
  File "/home/airflow/.local/lib/python3.7/site-packages/pymongo/mongo_client.py", line 1320, in _select_server
    operation_id=operation_id,
  File "/home/airflow/.local/lib/python3.7/site-packages/pymongo/topology.py", line 374, in select_server
    operation_id=operation_id,
  File "/home/airflow/.local/lib/python3.7/site-packages/pymongo/topology.py", line 347, in _select_server
    selector, operation, server_selection_timeout, address, operation_id
  File "/home/airflow/.local/lib/python3.7/site-packages/pymongo/topology.py", line 254, in select_servers
    selector, server_timeout, operation, operation_id, address
  File "/home/airflow/.local/lib/python3.7/site-packages/pymongo/topology.py", line 304, in _select_servers_loop
    f"{self._error_message(selector)}, Timeout: {timeout}s, Topology Description: {self.description!r}"
pymongo.errors.ServerSelectionTimeoutError: localhost:27017: [Errno 111] Connection refused (configured timeouts: socketTimeoutMS: 20000.0ms, connectTimeoutMS: 20000.0ms), Timeout: 30s, Topology Description: <TopologyDescription id: 67518085e0516cc4d10f6813, topology_type: Unknown, servers: [<ServerDescription ('localhost', 27017) server_type: Unknown, rtt: None, error=AutoReconnect('localhost:27017: [Errno 111] Connection refused (configured timeouts: socketTimeoutMS: 20000.0ms, connectTimeoutMS: 20000.0ms)')>]>
[2024-12-05T10:29:55.957+0000] {taskinstance.py:1350} INFO - Marking task as FAILED. dag_id=etl_file_processing, task_id=etl_process_ih, execution_date=20241205T102420, start_date=20241205T102925, end_date=20241205T102955
[2024-12-05T10:29:55.995+0000] {standard_task_runner.py:109} ERROR - Failed to execute job 199 for task etl_process_ih (localhost:27017: [Errno 111] Connection refused (configured timeouts: socketTimeoutMS: 20000.0ms, connectTimeoutMS: 20000.0ms), Timeout: 30s, Topology Description: <TopologyDescription id: 67518085e0516cc4d10f6813, topology_type: Unknown, servers: [<ServerDescription ('localhost', 27017) server_type: Unknown, rtt: None, error=AutoReconnect('localhost:27017: [Errno 111] Connection refused (configured timeouts: socketTimeoutMS: 20000.0ms, connectTimeoutMS: 20000.0ms)')>]>; 125)
[2024-12-05T10:29:56.020+0000] {local_task_job_runner.py:225} INFO - Task exited with return code 1
[2024-12-05T10:29:56.073+0000] {taskinstance.py:2653} INFO - 0 downstream tasks scheduled from follow-on schedule check
