[2024-12-05T10:23:15.855+0000] {taskinstance.py:1103} INFO - Dependencies all met for dep_context=non-requeueable deps ti=<TaskInstance: etl_file_processing.etl_process_fr manual__2024-12-05T10:18:11.041689+00:00 [queued]>
[2024-12-05T10:23:15.868+0000] {taskinstance.py:1103} INFO - Dependencies all met for dep_context=requeueable deps ti=<TaskInstance: etl_file_processing.etl_process_fr manual__2024-12-05T10:18:11.041689+00:00 [queued]>
[2024-12-05T10:23:15.870+0000] {taskinstance.py:1308} INFO - Starting attempt 2 of 2
[2024-12-05T10:23:15.885+0000] {taskinstance.py:1327} INFO - Executing <Task(PythonOperator): etl_process_fr> on 2024-12-05 10:18:11.041689+00:00
[2024-12-05T10:23:15.894+0000] {standard_task_runner.py:57} INFO - Started process 85 to run task
[2024-12-05T10:23:15.899+0000] {standard_task_runner.py:84} INFO - Running: ['***', 'tasks', 'run', 'etl_file_processing', 'etl_process_fr', 'manual__2024-12-05T10:18:11.041689+00:00', '--job-id', '190', '--raw', '--subdir', 'DAGS_FOLDER/ETL_file_processing.py', '--cfg-path', '/tmp/tmp1ytig9xa']
[2024-12-05T10:23:15.901+0000] {standard_task_runner.py:85} INFO - Job 190: Subtask etl_process_fr
[2024-12-05T10:23:15.984+0000] {task_command.py:410} INFO - Running <TaskInstance: etl_file_processing.etl_process_fr manual__2024-12-05T10:18:11.041689+00:00 [running]> on host 56e009f5c9b1
[2024-12-05T10:23:16.063+0000] {taskinstance.py:1547} INFO - Exporting env vars: AIRFLOW_CTX_DAG_OWNER='***' AIRFLOW_CTX_DAG_ID='etl_file_processing' AIRFLOW_CTX_TASK_ID='etl_process_fr' AIRFLOW_CTX_EXECUTION_DATE='2024-12-05T10:18:11.041689+00:00' AIRFLOW_CTX_TRY_NUMBER='2' AIRFLOW_CTX_DAG_RUN_ID='manual__2024-12-05T10:18:11.041689+00:00'
[2024-12-05T10:23:16.095+0000] {taskinstance.py:1824} ERROR - Task failed with exception
Traceback (most recent call last):
  File "/home/airflow/.local/lib/python3.7/site-packages/airflow/operators/python.py", line 181, in execute
    return_value = self.execute_callable()
  File "/home/airflow/.local/lib/python3.7/site-packages/airflow/operators/python.py", line 198, in execute_callable
    return self.python_callable(*self.op_args, **self.op_kwargs)
  File "/opt/airflow/dags/ETL_file_processing.py", line 31, in etl_process_fr
    db = client[DB_NAME]
  File "/home/airflow/.local/lib/python3.7/site-packages/pymongo/mongo_client.py", line 1641, in __getitem__
    return database.Database(self, name)
  File "/home/airflow/.local/lib/python3.7/site-packages/pymongo/database.py", line 136, in __init__
    raise TypeError("name must be an instance of str")
TypeError: name must be an instance of str
[2024-12-05T10:23:16.112+0000] {taskinstance.py:1350} INFO - Marking task as FAILED. dag_id=etl_file_processing, task_id=etl_process_fr, execution_date=20241205T101811, start_date=20241205T102315, end_date=20241205T102316
[2024-12-05T10:23:16.122+0000] {standard_task_runner.py:109} ERROR - Failed to execute job 190 for task etl_process_fr (name must be an instance of str; 85)
[2024-12-05T10:23:16.164+0000] {local_task_job_runner.py:225} INFO - Task exited with return code 1
[2024-12-05T10:23:16.203+0000] {taskinstance.py:2653} INFO - 0 downstream tasks scheduled from follow-on schedule check
