[2024-12-04T13:59:59.477+0000] {taskinstance.py:1103} INFO - Dependencies all met for dep_context=non-requeueable deps ti=<TaskInstance: FoReport_file_processing.etl_process_request manual__2024-12-04T13:54:27.594718+00:00 [queued]>
[2024-12-04T13:59:59.484+0000] {taskinstance.py:1103} INFO - Dependencies all met for dep_context=requeueable deps ti=<TaskInstance: FoReport_file_processing.etl_process_request manual__2024-12-04T13:54:27.594718+00:00 [queued]>
[2024-12-04T13:59:59.484+0000] {taskinstance.py:1308} INFO - Starting attempt 2 of 2
[2024-12-04T13:59:59.495+0000] {taskinstance.py:1327} INFO - Executing <Task(PythonOperator): etl_process_request> on 2024-12-04 13:54:27.594718+00:00
[2024-12-04T13:59:59.507+0000] {standard_task_runner.py:57} INFO - Started process 172 to run task
[2024-12-04T13:59:59.515+0000] {standard_task_runner.py:84} INFO - Running: ['***', 'tasks', 'run', 'FoReport_file_processing', 'etl_process_request', 'manual__2024-12-04T13:54:27.594718+00:00', '--job-id', '43', '--raw', '--subdir', 'DAGS_FOLDER/FoReport_file_processing.py', '--cfg-path', '/tmp/tmpi3vr6lld']
[2024-12-04T13:59:59.518+0000] {standard_task_runner.py:85} INFO - Job 43: Subtask etl_process_request
[2024-12-04T13:59:59.575+0000] {task_command.py:410} INFO - Running <TaskInstance: FoReport_file_processing.etl_process_request manual__2024-12-04T13:54:27.594718+00:00 [running]> on host effe9442f8f2
[2024-12-04T13:59:59.659+0000] {taskinstance.py:1547} INFO - Exporting env vars: AIRFLOW_CTX_DAG_OWNER='***' AIRFLOW_CTX_DAG_ID='FoReport_file_processing' AIRFLOW_CTX_TASK_ID='etl_process_request' AIRFLOW_CTX_EXECUTION_DATE='2024-12-04T13:54:27.594718+00:00' AIRFLOW_CTX_TRY_NUMBER='2' AIRFLOW_CTX_DAG_RUN_ID='manual__2024-12-04T13:54:27.594718+00:00'
[2024-12-04T14:00:00.572+0000] {taskinstance.py:1824} ERROR - Task failed with exception
Traceback (most recent call last):
  File "/home/airflow/.local/lib/python3.7/site-packages/airflow/operators/python.py", line 181, in execute
    return_value = self.execute_callable()
  File "/home/airflow/.local/lib/python3.7/site-packages/airflow/operators/python.py", line 198, in execute_callable
    return self.python_callable(*self.op_args, **self.op_kwargs)
  File "/opt/airflow/dags/FoReport_file_processing.py", line 112, in etl_process_request
    cleaned_df = merged_df.drop_duplicates(subset=["Room_Number", "Arrival", "Depart"], keep="last")
  File "/home/airflow/.local/lib/python3.7/site-packages/pandas/util/_decorators.py", line 311, in wrapper
    return func(*args, **kwargs)
  File "/home/airflow/.local/lib/python3.7/site-packages/pandas/core/frame.py", line 6063, in drop_duplicates
    duplicated = self.duplicated(subset, keep=keep)
  File "/home/airflow/.local/lib/python3.7/site-packages/pandas/core/frame.py", line 6197, in duplicated
    raise KeyError(diff)
KeyError: Index(['Arrival', 'Depart', 'Room_Number'], dtype='object')
[2024-12-04T14:00:00.612+0000] {taskinstance.py:1350} INFO - Marking task as FAILED. dag_id=FoReport_file_processing, task_id=etl_process_request, execution_date=20241204T135427, start_date=20241204T135959, end_date=20241204T140000
[2024-12-04T14:00:00.627+0000] {standard_task_runner.py:109} ERROR - Failed to execute job 43 for task etl_process_request (Index(['Arrival', 'Depart', 'Room_Number'], dtype='object'); 172)
[2024-12-04T14:00:00.666+0000] {local_task_job_runner.py:225} INFO - Task exited with return code 1
[2024-12-04T14:00:00.710+0000] {taskinstance.py:2653} INFO - 0 downstream tasks scheduled from follow-on schedule check
