[2024-12-04T14:29:00.937+0000] {taskinstance.py:1103} INFO - Dependencies all met for dep_context=non-requeueable deps ti=<TaskInstance: FoReport_file_processing.etl_merge_FO manual__2024-12-04T14:27:07.572431+00:00 [queued]>
[2024-12-04T14:29:00.986+0000] {taskinstance.py:1103} INFO - Dependencies all met for dep_context=requeueable deps ti=<TaskInstance: FoReport_file_processing.etl_merge_FO manual__2024-12-04T14:27:07.572431+00:00 [queued]>
[2024-12-04T14:29:00.988+0000] {taskinstance.py:1308} INFO - Starting attempt 1 of 2
[2024-12-04T14:29:01.086+0000] {taskinstance.py:1327} INFO - Executing <Task(PythonOperator): etl_merge_FO> on 2024-12-04 14:27:07.572431+00:00
[2024-12-04T14:29:01.133+0000] {standard_task_runner.py:57} INFO - Started process 342 to run task
[2024-12-04T14:29:01.164+0000] {standard_task_runner.py:84} INFO - Running: ['***', 'tasks', 'run', 'FoReport_file_processing', 'etl_merge_FO', 'manual__2024-12-04T14:27:07.572431+00:00', '--job-id', '60', '--raw', '--subdir', 'DAGS_FOLDER/FoReport_file_processing.py', '--cfg-path', '/tmp/tmp98e5qqt1']
[2024-12-04T14:29:01.169+0000] {standard_task_runner.py:85} INFO - Job 60: Subtask etl_merge_FO
[2024-12-04T14:29:01.367+0000] {task_command.py:410} INFO - Running <TaskInstance: FoReport_file_processing.etl_merge_FO manual__2024-12-04T14:27:07.572431+00:00 [running]> on host effe9442f8f2
[2024-12-04T14:29:02.361+0000] {taskinstance.py:1547} INFO - Exporting env vars: AIRFLOW_CTX_DAG_OWNER='***' AIRFLOW_CTX_DAG_ID='FoReport_file_processing' AIRFLOW_CTX_TASK_ID='etl_merge_FO' AIRFLOW_CTX_EXECUTION_DATE='2024-12-04T14:27:07.572431+00:00' AIRFLOW_CTX_TRY_NUMBER='1' AIRFLOW_CTX_DAG_RUN_ID='manual__2024-12-04T14:27:07.572431+00:00'
[2024-12-04T14:29:03.263+0000] {taskinstance.py:1824} ERROR - Task failed with exception
Traceback (most recent call last):
  File "/home/airflow/.local/lib/python3.7/site-packages/airflow/operators/python.py", line 181, in execute
    return_value = self.execute_callable()
  File "/home/airflow/.local/lib/python3.7/site-packages/airflow/operators/python.py", line 198, in execute_callable
    return self.python_callable(*self.op_args, **self.op_kwargs)
  File "/opt/airflow/dags/FoReport_file_processing.py", line 139, in etl_merge_FO
    escort_data = list(escort_etl_collection)
TypeError: 'Collection' object is not iterable
[2024-12-04T14:29:03.379+0000] {taskinstance.py:1350} INFO - Marking task as UP_FOR_RETRY. dag_id=FoReport_file_processing, task_id=etl_merge_FO, execution_date=20241204T142707, start_date=20241204T142900, end_date=20241204T142903
[2024-12-04T14:29:03.467+0000] {standard_task_runner.py:109} ERROR - Failed to execute job 60 for task etl_merge_FO ('Collection' object is not iterable; 342)
[2024-12-04T14:29:03.519+0000] {local_task_job_runner.py:225} INFO - Task exited with return code 1
[2024-12-04T14:29:03.615+0000] {taskinstance.py:2653} INFO - 0 downstream tasks scheduled from follow-on schedule check
